<?xml version="1.0"?>
<robot
	xmlns:xacro="http://www.ros.org/wiki/xacro"
	name="arm_model">

	<xacro:include filename="$(find arm_model)/xacro/macros.xacro" />

	<link name="arm_base_link">
		<visual>
			<geometry>
				<cylinder length="0.045" radius="0.055"/>
			</geometry>
			<material name="silver">
				<color rgba="0.75 0.75 0.75 1"/>
			</material>
			<origin rpy="0 0 0" xyz="0 0 0"/>
		</visual>
		<collision>
			<geometry>
				<cylinder length="0.045" radius="0.055"/>
			</geometry>
			<origin rpy="0 0 0" xyz="0 0 0"/>
		</collision>
		<inertial>
			<mass value="1.0"/>
			<origin rpy="0 0 0" xyz="0 0 0"/>
			<xacro:cylinder_inertia mass="1" r="0.055" l="0.05" />
		</inertial>
	</link>
	<!--joint name="fixed" type="fixed">
		<parent link="world"/>
		<child link="arm_base_link"/>
	</joint-->
	<link name="turntable">
		<visual>
			<geometry>
				<cylinder length="0.005" radius="0.055"/>
			</geometry>
			<material name="silver">
				<color rgba="0.75 0.75 0.75 1"/>
			</material>
			<origin rpy="0 0 0" xyz="0 0 0"/>
		</visual>
		<collision>
			<geometry>
				<cylinder length="0.005" radius="0.055"/>
			</geometry>
			<origin rpy="0 0 0" xyz="0 0 0"/>
		</collision>
		<inertial>
			<mass value="1.0"/>
			<origin rpy="0 0 0" xyz="0 0 0"/>
			<xacro:cylinder_inertia mass="1" r="0.055" l="0.005" />
		</inertial>
	</link>
	<joint name="turn" type="continuous">
		<axis xyz="0 0 1"/>
		<parent link="arm_base_link"/>
		<child link="turntable"/>
		<origin rpy="0 0 0" xyz="0.0 0.0 0.045"/>
	</joint>
	<link name="upper_arm">
		<visual>
			<geometry>
				<cylinder length="0.12" radius="0.0275"/>
			</geometry>
			<material name="silver"/>
			<origin rpy="0 0 0" xyz="0 0 0"/>
		</visual>
		<collision>
			<geometry>
				<<cylinder length="0.12" radius="0.0275"/>
			</geometry>
			<origin rpy="0 0 0" xyz="0 0 0"/>
		</collision>
		<inertial>
			<mass value="1.0"/>
			<origin rpy="0 0 0" xyz="0 0 0"/>
			<xacro:cylinder_inertia mass="1" r="0.0275" l="0.12" />
		</inertial>
	</link>
	<joint name="shoulder" type="continuous">
		<axis xyz="0 1 0"/>
		<parent link="turntable"/>
		<child link="upper_arm"/>
		<origin rpy="0 1.5708 0" xyz="0.0 -0.1 0.45"/>
	</joint>
	<link name="lower_arm">
		<visual>
			<geometry>
				<cylinder length="0.4" radius="0.05"/>
			</geometry>
			<material name="silver"/>
			<origin rpy="0 0 0" xyz="0 0 0.2"/>
		</visual>
		<collision>
			<geometry>
				<cylinder length="0.4" radius="0.05"/>
			</geometry>
			<origin rpy="0 0 0" xyz="0 0 0.2"/>
		</collision>
		<inertial>
			<mass value="1.0"/>
			<origin rpy="0 0 0" xyz="0 0 0.2"/>
			<inertia ixx="0.01396" iyy="0.01396" izz="0.00125"
			ixy="0" ixz="0" iyz="0"/>
		</inertial>
	</link>
	<joint name="elbow" type="continuous">
		<axis xyz="0 1 0"/>
		<parent link="upper_arm"/>
		<child link="lower_arm"/>
		<origin rpy="0 0 0" xyz="0.0 0.1 0.35"/>
	</joint>
	<link name="hand">
		<visual>
			<geometry>
				<box size="0.05 0.05 0.05"/>
			</geometry>
			<material name="silver"/>
		</visual>
		<collision>
			<geometry>
				<box size="0.05 0.05 0.05"/>
			</geometry>
		</collision>
		<inertial>
			<mass value="1.0"/>
			<inertia ixx="0.00042" iyy="0.00042" izz="0.00042"
			ixy="0" ixz="0" iyz="0"/>
		</inertial>
	</link>
	<joint name="wrist" type="continuous">
		<axis xyz="0 1 0"/>
		<parent link="lower_arm"/>
		<child link="hand"/>
		<origin rpy="0 0 0" xyz="0.0 0.0 0.425"/>
	</joint>

	<!--Transmission Descriptions-->
	<transmission name="tran0">
		<type>transmission_interface/SimpleTransmission</type>
		<joint name="hip">
			<hardwareInterface>PositionJointInterface</hardwareInterface>
		</joint>
		<actuator name="motor0">
			<hardwareInterface>PositionJointInterface</hardwareInterface>
			<mechanicalReduction>1</mechanicalReduction>
		</actuator>
	</transmission>
	<transmission name="tran1">
		<type>transmission_interface/SimpleTransmission</type>
		<joint name="shoulder">
			<hardwareInterface>PositionJointInterface</hardwareInterface>
		</joint>
		<actuator name="motor1">
			<hardwareInterface>PositionJointInterface</hardwareInterface>
			<mechanicalReduction>1</mechanicalReduction>
		</actuator>
	</transmission>
	<transmission name="tran2">
		<type>transmission_interface/SimpleTransmission</type>
		<joint name="elbow">
			<hardwareInterface>PositionJointInterface</hardwareInterface>
		</joint>
		<actuator name="motor2">
			<hardwareInterface>PositionJointInterface</hardwareInterface>
			<mechanicalReduction>1</mechanicalReduction>
		</actuator>
	</transmission>
	<transmission name="tran3">
		<type>transmission_interface/SimpleTransmission</type>
		<joint name="wrist">
			<hardwareInterface>PositionJointInterface</hardwareInterface>
		</joint>
		<actuator name="motor3">
			<hardwareInterface>PositionJointInterface</hardwareInterface>
			<mechanicalReduction>1</mechanicalReduction>
		</actuator>
	</transmission>

	<!-- Gazebo Plugins -->
	<gazebo>
		<!--ros_control plugin-->
		<plugin name="control" filename="libgazebo_ros_control.so"/>
		<!-- joint_state_publisher plugin -->
		<plugin name="joint_state_publisher" filename="libgazebo_ros_joint_state_publisher.so">
				<jointName>hip, shoulder, elbow, wrist</jointName>
		</plugin>
	</gazebo>
</robot>
