<?xml version="1.0" encoding="utf-8"?>
<!-- =================================================================================== -->
<!-- |    This document was autogenerated by xacro from manipulator.urdf.xacro         | -->
<!-- |    EDITING THIS FILE BY HAND IS NOT RECOMMENDED                                 | -->
<!-- =================================================================================== -->
<robot name="manipulator_model">
  <link name="world"/>
  <link name="rotate_moving_base">
    <inertial>
      <mass value="1.0"/>
      <origin rpy="0 0 0" xyz="0 0 0.0625"/>
      <inertia ixx="0.000964583333333" ixy="0" ixz="0" iyy="0.000964583333333" iyz="0" izz="0.0015125"/>
    </inertial>
  </link>
  <joint name="move_rotate" type="continuous">
    <axis xyz="0 0 1"/>
    <parent link="world"/>
    <child link="rotate_moving_base"/>
    <origin rpy="0 0 0" xyz="0.0 0.0 0.0"/>
  </joint>
  <link name="forward_moving_base">
    <inertial>
      <mass value="1.0"/>
      <origin rpy="0 0 0" xyz="0 0 0.0625"/>
      <inertia ixx="0.000964583333333" ixy="0" ixz="0" iyy="0.000964583333333" iyz="0" izz="0.0015125"/>
    </inertial>
  </link>
  <joint name="move_forward" type="prismatic">
    <axis xyz="1 0 0"/>
    <parent link="rotate_moving_base"/>
    <child link="forward_moving_base"/>
    <limit effort="1000.0" lower="-1" upper="1" velocity="0.5"/>
    <origin rpy="0 0 0" xyz="0.0 0.0 0.0"/>
  </joint>
  <joint name="fixed" type="fixed">
    <parent link="forward_moving_base"/>
    <child link="manipulator_base_link"/>
  </joint>
  <link name="manipulator_base_link">
    <visual>
      <geometry>
        <cylinder length="0.125" radius="0.175"/>
      </geometry>
      <material name="silver">
        <color rgba="0.75 0.75 0.75 1"/>
      </material>
      <origin rpy="0 0 0" xyz="0 0 0.0625"/>
    </visual>
    <collision>
      <geometry>
        <cylinder length="0.125" radius="0.175"/>
      </geometry>
      <origin rpy="0 0 0" xyz="0 0 0.0625"/>
    </collision>
    <inertial>
      <mass value="1.0"/>
      <origin rpy="0 0 0" xyz="0 0 0.0625"/>
      <inertia ixx="0.00270833333333" ixy="0" ixz="0" iyy="0.00270833333333" iyz="0" izz="0.005"/>
    </inertial>
  </link>
  <link name="turntable">
    <visual>
      <geometry>
        <cylinder length="0.03" radius="0.055"/>
      </geometry>
      <material name="silver">
        <color rgba="0.75 0.75 0.75 1"/>
      </material>
      <origin rpy="0 0 0" xyz="0 0 0.015"/>
    </visual>
    <collision>
      <geometry>
        <cylinder length="0.03" radius="0.055"/>
      </geometry>
      <origin rpy="0 0 0" xyz="0 0 0.015"/>
    </collision>
    <inertial>
      <mass value="1.0"/>
      <origin rpy="0 0 0" xyz="0 0 0.015"/>
      <inertia ixx="0.00083125" ixy="0" ixz="0" iyy="0.00083125" iyz="0" izz="0.0015125"/>
    </inertial>
  </link>
  <joint name="turn" type="continuous">
    <axis xyz="0 0 1"/>
    <parent link="manipulator_base_link"/>
    <child link="turntable"/>
    <origin rpy="0 0 0" xyz="0.0 0.0 0.125"/>
  </joint>
  <link name="upper_arm">
    <visual>
      <geometry>
        <cylinder length="0.12" radius="0.0275"/>
      </geometry>
      <material name="silver"/>
      <origin rpy="-1.5708 0 0" xyz="0 0.06 0"/>
    </visual>
    <collision>
      <geometry>
        <cylinder length="0.12" radius="0.0275"/>
      </geometry>
      <origin rpy="-1.5708 0 0" xyz="0 0.06 0"/>
    </collision>
    <inertial>
      <mass value="1.0"/>
      <origin rpy="-1.5708 0 0" xyz="0 0.06 0"/>
      <inertia ixx="0.0013890625" ixy="0" ixz="0" iyy="0.0013890625" iyz="0" izz="0.000378125"/>
    </inertial>
  </link>
  <joint name="shoulder" type="continuous">
    <axis xyz="0 0 1"/>
    <parent link="turntable"/>
    <child link="upper_arm"/>
    <origin rpy="1.5708 0 0" xyz="0.0 0.0 0.0575"/>
  </joint>
  <link name="middle_arm">
    <visual>
      <geometry>
        <cylinder length="0.12" radius="0.0275"/>
      </geometry>
      <material name="silver"/>
      <origin rpy="-1.5708 0 0" xyz="0 0.06 0.0555"/>
    </visual>
    <collision>
      <geometry>
        <cylinder length="0.12" radius="0.0275"/>
      </geometry>
      <origin rpy="-1.5708 0 0" xyz="0 0.06 0.0555"/>
    </collision>
    <inertial>
      <mass value="1.0"/>
      <origin rpy="-1.5708 0 0" xyz="0 0.06 0.0555"/>
      <inertia ixx="0.0013890625" ixy="0" ixz="0" iyy="0.0013890625" iyz="0" izz="0.000378125"/>
    </inertial>
  </link>
  <joint name="elbow" type="continuous">
    <axis xyz="0 0 1"/>
    <parent link="upper_arm"/>
    <child link="middle_arm"/>
    <origin rpy="0 0 0" xyz="0 0.12 0"/>
  </joint>
  <link name="lower_arm">
    <visual>
      <geometry>
        <cylinder length="0.055" radius="0.0275"/>
      </geometry>
      <material name="silver"/>
      <origin rpy="-1.5708 0 0" xyz="0 0.0275 0"/>
    </visual>
    <collision>
      <geometry>
        <cylinder length="0.055" radius="0.0275"/>
      </geometry>
      <origin rpy="-1.5708 0 0" xyz="0 0.0275 0"/>
    </collision>
    <inertial>
      <mass value="1.0"/>
      <origin rpy="-1.5708 0 0" xyz="0 0.0275 0"/>
      <inertia ixx="0.000441145833333" ixy="0" ixz="0" iyy="0.000441145833333" iyz="0" izz="0.000378125"/>
    </inertial>
  </link>
  <joint name="another_elbow" type="continuous">
    <axis xyz="0 0 1"/>
    <parent link="middle_arm"/>
    <child link="lower_arm"/>
    <origin rpy="0 0 0" xyz="0 0.12 0"/>
  </joint>
  <link name="hand">
    <visual>
      <geometry>
        <box size="0.03 0.03 0.03"/>
      </geometry>
      <material name="silver"/>
      <origin rpy="0 0 0" xyz="0 0 0.015"/>
    </visual>
    <collision>
      <geometry>
        <box size="0.03 0.03 0.03"/>
      </geometry>
      <origin rpy="0 0 0" xyz="0 0 0.015"/>
    </collision>
    <inertial>
      <mass value="1.0"/>
      <origin rpy="0 0 0" xyz="0 0 0.015"/>
      <inertia ixx="0.00015" ixy="0" ixz="0" iyy="0.00015" iyz="0" izz="0.0009"/>
    </inertial>
  </link>
  <joint name="wrist" type="fixed">
    <parent link="lower_arm"/>
    <child link="hand"/>
    <origin rpy="-1.5708 0 0" xyz="0.0 0.055 0.0"/>
  </joint>
  <transmission name="tran0">
    <type>transmission_interface/SimpleTransmission</type>
    <joint name="turn">
      <hardwareInterface>hardware_interface/EffortJointInterface</hardwareInterface>
    </joint>
    <actuator name="motor0">
      <hardwareInterface>hardware_interface/EffortJointInterface</hardwareInterface>
      <mechanicalReduction>1</mechanicalReduction>
    </actuator>
  </transmission>
  <transmission name="tran1">
    <type>transmission_interface/SimpleTransmission</type>
    <joint name="shoulder">
      <hardwareInterface>hardware_interface/EffortJointInterface</hardwareInterface>
    </joint>
    <actuator name="motor1">
      <hardwareInterface>hardware_interface/EffortJointInterface</hardwareInterface>
      <mechanicalReduction>1</mechanicalReduction>
    </actuator>
  </transmission>
  <transmission name="tran2">
    <type>transmission_interface/SimpleTransmission</type>
    <joint name="elbow">
      <hardwareInterface>hardware_interface/EffortJointInterface</hardwareInterface>
    </joint>
    <actuator name="motor2">
      <hardwareInterface>hardware_interface/EffortJointInterface</hardwareInterface>
      <mechanicalReduction>1</mechanicalReduction>
    </actuator>
  </transmission>
  <transmission name="tran3">
    <type>transmission_interface/SimpleTransmission</type>
    <joint name="another_elbow">
      <hardwareInterface>hardware_interface/EffortJointInterface</hardwareInterface>
    </joint>
    <actuator name="motor3">
      <hardwareInterface>hardware_interface/EffortJointInterface</hardwareInterface>
      <mechanicalReduction>1</mechanicalReduction>
    </actuator>
  </transmission>
  <transmission name="tran4">
    <type>transmission_interface/SimpleTransmission</type>
    <joint name="move_rotate">
      <hardwareInterface>hardware_interface/EffortJointInterface</hardwareInterface>
    </joint>
    <actuator name="motor4">
      <hardwareInterface>hardware_interface/EffortJointInterface</hardwareInterface>
      <mechanicalReduction>1</mechanicalReduction>
    </actuator>
  </transmission>
  <transmission name="tran5">
    <type>transmission_interface/SimpleTransmission</type>
    <joint name="move_forward">
      <hardwareInterface>hardware_interface/EffortJointInterface</hardwareInterface>
    </joint>
    <actuator name="motor5">
      <hardwareInterface>hardware_interface/EffortJointInterface</hardwareInterface>
      <mechanicalReduction>1</mechanicalReduction>
    </actuator>
  </transmission>
  <!-- Gazebo Plugins -->
  <gazebo>
    <!-- ros_control plugin -->
    <plugin filename="libgazebo_ros_control.so" name="control"/>
    <!-- joint_state_publisher plugin -->
    <plugin filename="libgazebo_ros_joint_state_publisher.so" name="joint_state_publisher">
      <jointName>turn, shoulder, elbow, another_elbow, move_rotate, move_forward</jointName>
    </plugin>
  </gazebo>
</robot>

