<?xml version="1.0"?>
<robot
	xmlns:xacro="http://www.ros.org/wiki/xacro"
	name="manipulator_model">

	<xacro:include filename="$(find manipulator_model)/xacro/inertia_macros.xacro" />
	<xacro:include filename="$(find manipulator_model)/xacro/transmission_macros.xacro" />

	<xacro:macro name="manipulator_model">
		<link name="world"/>
		<link name="rotate_moving_base">
			<inertial>
				<mass value="1.0"/>
				<origin rpy="0 0 0" xyz="0 0 0.0625"/>
				<xacro:cylinder_inertia mass="1" r="0.055" l="0.05" />
			</inertial>
		</link>
		<joint name="move_rotate" type="continuous">
			<axis xyz="0 0 1"/>
			<parent link="world"/>
			<child link="rotate_moving_base"/>
			<origin rpy="0 0 0" xyz="0.0 0.0 0.0"/>
		</joint>
		<link name="forward_moving_base">
			<inertial>
				<mass value="1.0"/>
				<origin rpy="0 0 0" xyz="0 0 0.0625"/>
				<xacro:cylinder_inertia mass="1" r="0.055" l="0.05" />
			</inertial>
		</link>
		<joint name="move_forward" type="prismatic">
			<axis xyz="1 0 0"/>
			<parent link="rotate_moving_base"/>
			<child link="forward_moving_base"/>
			<limit effort="1000.0" lower="-1" upper="1" velocity="0.5"/>
			<origin rpy="0 0 0" xyz="0.0 0.0 0.0"/>
		</joint>
		<joint name="fixed" type="fixed">
			<parent link="forward_moving_base"/>
			<child link="manipulator_base_link"/>
		</joint>
		<link name="manipulator_base_link">
			<visual>
				<geometry>
					<cylinder length="0.125" radius="0.175"/>
				</geometry>
				<material name="silver">
					<color rgba="0.75 0.75 0.75 1"/>
				</material>
				<origin rpy="0 0 0" xyz="0 0 0.0625"/>
			</visual>
			<collision>
				<geometry>
					<cylinder length="0.125" radius="0.175"/>
				</geometry>
				<origin rpy="0 0 0" xyz="0 0 0.0625"/>
			</collision>
			<inertial>
				<mass value="1.0"/>
				<origin rpy="0 0 0" xyz="0 0 0.0625"/>
				<xacro:cylinder_inertia mass="1" r="0.1" l="0.05" />
			</inertial>
		</link>
		<link name="turntable">
			<visual>
				<geometry>
					<cylinder length="0.03" radius="0.055"/>
				</geometry>
				<material name="silver">
					<color rgba="0.75 0.75 0.75 1"/>
				</material>
				<origin rpy="0 0 0" xyz="0 0 0.015"/>
			</visual>
			<collision>
				<geometry>
					<cylinder length="0.03" radius="0.055"/>
				</geometry>
				<origin rpy="0 0 0" xyz="0 0 0.015"/>
			</collision>
			<inertial>
				<mass value="1.0"/>
				<origin rpy="0 0 0" xyz="0 0 0.015"/>
				<xacro:cylinder_inertia mass="1" r="0.055" l="0.03" />
			</inertial>
		</link>
		<joint name="turn" type="continuous">
			<axis xyz="0 0 1"/>
			<parent link="manipulator_base_link"/>
			<child link="turntable"/>
			<origin rpy="0 0 0" xyz="0.0 0.0 0.125"/>
		</joint>
		<link name="upper_arm">
			<visual>
				<geometry>
					<cylinder length="0.12" radius="0.0275"/>
				</geometry>
				<material name="silver"/>
				<origin rpy="-1.5708 0 0" xyz="0 0.06 0"/>
			</visual>
			<collision>
				<geometry>
					<cylinder length="0.12" radius="0.0275"/>
				</geometry>
				<origin rpy="-1.5708 0 0" xyz="0 0.06 0"/>
			</collision>
			<inertial>
				<mass value="1.0"/>
				<origin rpy="-1.5708 0 0" xyz="0 0.06 0"/>
				<xacro:cylinder_inertia mass="1" r="0.0275" l="0.12" />
			</inertial>
		</link>
		<joint name="shoulder" type="continuous">
			<axis xyz="0 0 1"/>
			<parent link="turntable"/>
			<child link="upper_arm"/>
			<origin rpy="1.5708 0 0" xyz="0.0 0.0 0.0575"/>
		</joint>
		<link name="middle_arm">
			<visual>
				<geometry>
					<cylinder length="0.12" radius="0.0275"/>
				</geometry>
				<material name="silver"/>
				<origin rpy="-1.5708 0 0" xyz="0 0.06 0.0555"/>
			</visual>
			<collision>
				<geometry>
					<cylinder length="0.12" radius="0.0275"/>
				</geometry>
				<origin rpy="-1.5708 0 0" xyz="0 0.06 0.0555"/>
			</collision>
			<inertial>
				<mass value="1.0"/>
				<origin rpy="-1.5708 0 0" xyz="0 0.06 0.0555"/>
				<xacro:cylinder_inertia mass="1" r="0.0275" l="0.12" />
			</inertial>
		</link>
		<joint name="elbow" type="continuous">
			<axis xyz="0 0 1"/>
			<parent link="upper_arm"/>
			<child link="middle_arm"/>
			<origin rpy="0 0 0" xyz="0 0.12 0"/>
		</joint>
		<link name="lower_arm">
			<visual>
				<geometry>
					<cylinder length="0.055" radius="0.0275"/>
				</geometry>
				<material name="silver"/>
				<origin rpy="-1.5708 0 0" xyz="0 0.0275 0"/>
			</visual>
			<collision>
				<geometry>
					<cylinder length="0.055" radius="0.0275"/>
				</geometry>
				<origin rpy="-1.5708 0 0" xyz="0 0.0275 0"/>
			</collision>
			<inertial>
				<mass value="1.0"/>
				<origin rpy="-1.5708 0 0" xyz="0 0.0275 0"/>
				<xacro:cylinder_inertia mass="1" r="0.0275" l="0.055" />
			</inertial>
		</link>
		<joint name="another_elbow" type="continuous">
			<axis xyz="0 0 1"/>
			<parent link="middle_arm"/>
			<child link="lower_arm"/>
			<origin rpy="0 0 0" xyz="0 0.12 0"/>
		</joint>
		<link name="hand">
			<visual>
				<geometry>
					<box size="0.03 0.03 0.03"/>
				</geometry>
				<material name="silver"/>
				<origin rpy="0 0 0" xyz="0 0 0.015"/>
			</visual>
			<collision>
				<geometry>
					<box size="0.03 0.03 0.03"/>
				</geometry>
				<origin rpy="0 0 0" xyz="0 0 0.015"/>
			</collision>
			<inertial>
				<mass value="1.0"/>
				<origin rpy="0 0 0" xyz="0 0 0.015"/>
				<xacro:box_inertia mass="1" x="0.03" y="0.03" z="0.03" />
			</inertial>
		</link>
		<joint name="wrist" type="fixed">
			<parent link="lower_arm"/>
			<child link="hand"/>
			<origin rpy="-1.5708 0 0" xyz="0.0 0.055 0.0"/>
		</joint>

		<!--Transmission Descriptions-->
		<xacro:position_transmission name="tran0" joint="turn" actuator="motor0"/>
		<xacro:position_transmission name="tran1" joint="shoulder" actuator="motor1"/>
		<xacro:position_transmission name="tran2" joint="elbow" actuator="motor2"/>
		<xacro:position_transmission name="tran3" joint="another_elbow" actuator="motor3"/>
		<xacro:position_transmission name="tran4" joint="move_rotate" actuator="motor4"/>
		<xacro:position_transmission name="tran5" joint="move_forward" actuator="motor5"/>

		<!-- Gazebo Plugins -->
		<gazebo>
			<!-- ros_control plugin -->
			<plugin name="control" filename="libgazebo_ros_control.so"/>
			<!-- joint_state_publisher plugin -->
			<plugin name="joint_state_publisher" filename="libgazebo_ros_joint_state_publisher.so">
					<jointName>turn, shoulder, elbow, another_elbow, move_rotate, move_forward</jointName>
			</plugin>
		</gazebo>
	</xacro:macro>

	<xacro:manipulator_model/>
</robot>
